<?xml version="1.0" ?>
<!-- =================================================================================== -->
<!-- |    This document was autogenerated by xacro from vector.xacro                   | -->
<!-- |    EDITING THIS FILE BY HAND IS NOT RECOMMENDED                                 | -->
<!-- =================================================================================== -->
<robot name="vector">
  <link name="base_footprint"/>
  <joint name="base_footprint_joint" type="fixed">
    <origin rpy="0 0 0" xyz="0 0 0.027"/>
    <parent link="base_footprint"/>
    <child link="base_link"/>
  </joint>
  <!-- Body -->
  <link name="base_link">
    <visual>
      <geometry>
        <mesh filename="package://anki_description/meshes/vector_body.dae"/>
      </geometry>
    </visual>
    <collision>
      <origin rpy="0 0 0" xyz="0.0075 0.0 -0.01"/>
      <geometry>
        <box size="0.07 0.03 0.01"/>
        <!-- <mesh filename="package://anki_description/meshes/vector_body.dae"  /> -->
      </geometry>
    </collision>
    <inertial>
      <origin rpy="0 0 0" xyz="0.0075 0.0 -0.01"/>
      <geometry>
        <box size="0.073 0.043 0.061"/>
      </geometry>
      <mass value="0.16"/>
      <inertia ixx="7.426666666666666e-05" ixy="0" ixz="0" iyy="0.00012066666666666665" iyz="0" izz="0.00012066666666666665"/>
    </inertial>
  </link>
  <gazebo reference="base_link">
    <selfCollide>true</selfCollide>
    <mu1 value="200.0"/>
    <mu2 value="100.0"/>
    <kp value="10000000.0"/>
    <kd value="1.0"/>
  </gazebo>
  <!-- Head -->
  <link name="head">
    <visual>
      <geometry>
        <mesh filename="package://anki_description/meshes/vector_head.dae"/>
      </geometry>
    </visual>
    <collision>
      <geometry>
        <sphere radius="0.02"/>
      </geometry>
    </collision>
    <inertial>
      <geometry>
        <sphere radius="0.02"/>
      </geometry>
      <mass value="0.03"/>
      <inertia ixx="4.8e-06" ixy="0" ixz="0" iyy="4.8e-06" iyz="0" izz="4.8e-06"/>
    </inertial>
  </link>
  <gazebo reference="head">
    <mu1 value="200.0"/>
    <mu2 value="100.0"/>
    <kp value="10000000.0"/>
    <kd value="1.0"/>
  </gazebo>
  <!-- lifter -->
  <link name="full_lift">
    <visual>
      <geometry>
        <mesh filename="package://anki_description/meshes/vector_lift.dae"/>
      </geometry>
    </visual>
    <collision>
      <origin rpy="0 0 0" xyz="0.062 0.0 -0.015"/>
      <geometry>
        <box size="0.0075 0.05 0.025"/>
      </geometry>
    </collision>
    <inertial>
      <origin rpy="0 0 0" xyz="0.062 0.0 -0.015"/>
      <geometry>
        <box size="0.0075 0.05 0.025"/>
      </geometry>
      <mass value="0.05"/>
      <inertia ixx="1.3020833333333336e-05" ixy="0" ixz="0" iyy="2.838541666666667e-06" iyz="0" izz="2.838541666666667e-06"/>
    </inertial>
  </link>
  <gazebo reference="full_lift">
    <mu1 value="200.0"/>
    <mu2 value="100.0"/>
    <kp value="10000000.0"/>
    <kd value="1.0"/>
  </gazebo>
  <joint name="base_to_head" type="revolute">
    <parent link="base_link"/>
    <child link="head"/>
    <origin xyz="0.0174507 0 0.022003"/>
    <limit effort="100" lower="-0.52" upper="0.17" velocity="10"/>
    <!-- Damping breaks the model (?), keep it 0.0 -->
    <dynamics damping="0.0" friction="0.1"/>
    <axis xyz="0 1 0"/>
  </joint>
  <joint name="base_to_lift" type="revolute">
    <parent link="base_link"/>
    <child link="full_lift"/>
    <origin xyz="-0.005 0 0.013"/>
    <limit effort="10" lower="-0.8" upper="0" velocity="10"/>
    <dynamics damping="0.0" friction="0.1"/>
    <axis xyz="0 1 0"/>
  </joint>
  <!-- Transmissions for joints -->
  <transmission name="base_to_head_trans">
    <type>transmission_interface/SimpleTransmission</type>
    <joint name="base_to_head">
      <hardwareInterface>hardware_interface/PositionJointInterface</hardwareInterface>
    </joint>
    <actuator name="base_to_headMotor">
      <hardwareInterface>hardware_interface/PositionJointInterface</hardwareInterface>
      <mechanicalReduction>1</mechanicalReduction>
      <motorTorqueConstant>1</motorTorqueConstant>
    </actuator>
  </transmission>
  <transmission name="base_to_lift_trans">
    <type>transmission_interface/SimpleTransmission</type>
    <joint name="base_to_lift">
      <hardwareInterface>hardware_interface/PositionJointInterface</hardwareInterface>
    </joint>
    <actuator name="base_to_liftMotor">
      <hardwareInterface>hardware_interface/PositionJointInterface</hardwareInterface>
      <mechanicalReduction>1</mechanicalReduction>
      <motorTorqueConstant>1</motorTorqueConstant>
    </actuator>
  </transmission>
  <link name="front_left_wheel">
    <visual>
      <material name="black"/>
      <origin rpy="0 0 0" xyz="0 0 0"/>
      <geometry>
        <cylinder length="0.0116739" radius="0.01314"/>
      </geometry>
    </visual>
    <collision>
      <material name="black"/>
      <origin rpy="0 0 0" xyz="0 0 0"/>
      <geometry>
        <cylinder length="0.0116739" radius="0.01314"/>
      </geometry>
    </collision>
    <inertial>
      <origin rpy="0 0 0" xyz="0 0 0"/>
      <geometry>
        <cylinder length="0.0116739" radius="0.01314"/>
      </geometry>
      <mass value="0.01"/>
      <inertia ixx="5.4513975e-07" ixy="0" ixz="0" iyy="5.4513975e-07" iyz="0" izz="8.632980000000002e-07"/>
    </inertial>
  </link>
  <gazebo reference="front_left_wheel">
    <material>Gazebo/Grey</material>
  </gazebo>
  <joint name="front_left_wheel_joint" type="continuous">
    <parent link="base_link"/>
    <child link="front_left_wheel"/>
    <origin rpy="-1.5707963267948966 0 0" xyz="0.03 0.024 -0.012"/>
    <axis xyz="0 0 1"/>
  </joint>
  <transmission name="front_left_wheel_transmission">
    <type>transmission_interface/SimpleTransmission</type>
    <joint name="front_left_wheel_joint">
      <hardwareInterface>hardware_interface/VelocityJointInterface</hardwareInterface>
    </joint>
    <actuator name="front_left_wheel_motor">
      <hardwareInterface>hardware_interface/VelocityJointInterface</hardwareInterface>
      <mechanicalReduction>30</mechanicalReduction>
    </actuator>
  </transmission>
  <gazebo reference="front_left_wheel">
    <selfCollide>True</selfCollide>
    <!-- <mu1 value="200.0"/>
      <mu2 value="100.0"/>
      <kp value="10000000.0"/>
      <kd value="1.0"/> -->
  </gazebo>
  <link name="front_right_wheel">
    <visual>
      <material name="black"/>
      <origin rpy="0 0 0" xyz="0 0 0"/>
      <geometry>
        <cylinder length="0.0116739" radius="0.01314"/>
      </geometry>
    </visual>
    <collision>
      <material name="black"/>
      <origin rpy="0 0 0" xyz="0 0 0"/>
      <geometry>
        <cylinder length="0.0116739" radius="0.01314"/>
      </geometry>
    </collision>
    <inertial>
      <origin rpy="0 0 0" xyz="0 0 0"/>
      <geometry>
        <cylinder length="0.0116739" radius="0.01314"/>
      </geometry>
      <mass value="0.01"/>
      <inertia ixx="5.4513975e-07" ixy="0" ixz="0" iyy="5.4513975e-07" iyz="0" izz="8.632980000000002e-07"/>
    </inertial>
  </link>
  <gazebo reference="front_right_wheel">
    <material>Gazebo/Grey</material>
  </gazebo>
  <joint name="front_right_wheel_joint" type="continuous">
    <parent link="base_link"/>
    <child link="front_right_wheel"/>
    <origin rpy="-1.5707963267948966 0 0" xyz="0.03 -0.024 -0.012"/>
    <axis xyz="0 0 1"/>
  </joint>
  <transmission name="front_right_wheel_transmission">
    <type>transmission_interface/SimpleTransmission</type>
    <joint name="front_right_wheel_joint">
      <hardwareInterface>hardware_interface/VelocityJointInterface</hardwareInterface>
    </joint>
    <actuator name="front_right_wheel_motor">
      <hardwareInterface>hardware_interface/VelocityJointInterface</hardwareInterface>
      <mechanicalReduction>30</mechanicalReduction>
    </actuator>
  </transmission>
  <gazebo reference="front_right_wheel">
    <selfCollide>True</selfCollide>
    <!-- <mu1 value="200.0"/>
      <mu2 value="100.0"/>
      <kp value="10000000.0"/>
      <kd value="1.0"/> -->
  </gazebo>
  <link name="rear_left_wheel">
    <visual>
      <material name="black"/>
      <origin rpy="0 0 0" xyz="0 0 0"/>
      <geometry>
        <cylinder length="0.0116739" radius="0.008995"/>
      </geometry>
    </visual>
    <collision>
      <material name="black"/>
      <origin rpy="0 0 0" xyz="0 0 0"/>
      <geometry>
        <cylinder length="0.0116739" radius="0.008995"/>
      </geometry>
    </collision>
    <inertial>
      <origin rpy="0 0 0" xyz="0 0 0"/>
      <geometry>
        <cylinder length="0.0116739" radius="0.008995"/>
      </geometry>
      <mass value="0.01"/>
      <inertia ixx="3.157658125e-07" ixy="0" ixz="0" iyy="3.157658125e-07" iyz="0" izz="4.0455012499999993e-07"/>
    </inertial>
  </link>
  <gazebo reference="rear_left_wheel">
    <material>Gazebo/Grey</material>
  </gazebo>
  <joint name="rear_left_wheel_joint" type="continuous">
    <parent link="base_link"/>
    <child link="rear_left_wheel"/>
    <origin rpy="-1.5707963267948966 0 0" xyz="-0.017 0.024 -0.0151707"/>
    <axis xyz="0 0 1"/>
  </joint>
  <transmission name="rear_left_wheel_transmission">
    <type>transmission_interface/SimpleTransmission</type>
    <joint name="rear_left_wheel_joint">
      <hardwareInterface>hardware_interface/VelocityJointInterface</hardwareInterface>
    </joint>
    <actuator name="rear_left_wheel_motor">
      <hardwareInterface>hardware_interface/VelocityJointInterface</hardwareInterface>
      <mechanicalReduction>30</mechanicalReduction>
    </actuator>
  </transmission>
  <gazebo reference="rear_left_wheel">
    <selfCollide>True</selfCollide>
    <!-- <mu1 value="200.0"/>
      <mu2 value="100.0"/>
      <kp value="10000000.0"/>
      <kd value="1.0"/> -->
  </gazebo>
  <link name="rear_right_wheel">
    <visual>
      <material name="black"/>
      <origin rpy="0 0 0" xyz="0 0 0"/>
      <geometry>
        <cylinder length="0.0116739" radius="0.008995"/>
      </geometry>
    </visual>
    <collision>
      <material name="black"/>
      <origin rpy="0 0 0" xyz="0 0 0"/>
      <geometry>
        <cylinder length="0.0116739" radius="0.008995"/>
      </geometry>
    </collision>
    <inertial>
      <origin rpy="0 0 0" xyz="0 0 0"/>
      <geometry>
        <cylinder length="0.0116739" radius="0.008995"/>
      </geometry>
      <mass value="0.01"/>
      <inertia ixx="3.157658125e-07" ixy="0" ixz="0" iyy="3.157658125e-07" iyz="0" izz="4.0455012499999993e-07"/>
    </inertial>
  </link>
  <gazebo reference="rear_right_wheel">
    <material>Gazebo/Grey</material>
  </gazebo>
  <joint name="rear_right_wheel_joint" type="continuous">
    <parent link="base_link"/>
    <child link="rear_right_wheel"/>
    <origin rpy="-1.5707963267948966 0 0" xyz="-0.017 -0.024 -0.0151707"/>
    <axis xyz="0 0 1"/>
  </joint>
  <transmission name="rear_right_wheel_transmission">
    <type>transmission_interface/SimpleTransmission</type>
    <joint name="rear_right_wheel_joint">
      <hardwareInterface>hardware_interface/VelocityJointInterface</hardwareInterface>
    </joint>
    <actuator name="rear_right_wheel_motor">
      <hardwareInterface>hardware_interface/VelocityJointInterface</hardwareInterface>
      <mechanicalReduction>30</mechanicalReduction>
    </actuator>
  </transmission>
  <gazebo reference="rear_right_wheel">
    <selfCollide>True</selfCollide>
    <!-- <mu1 value="200.0"/>
      <mu2 value="100.0"/>
      <kp value="10000000.0"/>
      <kd value="1.0"/> -->
  </gazebo>
  <link name="left_belt">
    <visual>
      <geometry>
        <mesh filename="package://anki_description/meshes/cozmo_belt.dae"/>
      </geometry>
    </visual>
  </link>
  <joint name="wheel_left_belt" type="fixed">
    <parent link="base_link"/>
    <child link="left_belt"/>
    <origin xyz="0.00945088 0.024 -0.0133211"/>
  </joint>
  <link name="right_belt">
    <visual>
      <geometry>
        <mesh filename="package://anki_description/meshes/cozmo_belt.dae"/>
      </geometry>
    </visual>
  </link>
  <joint name="wheel_right_belt" type="fixed">
    <parent link="base_link"/>
    <child link="right_belt"/>
    <origin xyz="0.00945088 -0.024 -0.0133211"/>
  </joint>
  <gazebo>
    <plugin filename="libgazebo_ros_skid_steer_drive.so" name="skid_steer_drive_controller">
      <updateRate>25.0</updateRate>
      <robotNamespace>/</robotNamespace>
      <leftFrontJoint>front_left_wheel_joint</leftFrontJoint>
      <rightFrontJoint>front_right_wheel_joint</rightFrontJoint>
      <leftRearJoint>rear_left_wheel_joint</leftRearJoint>
      <rightRearJoint>rear_right_wheel_joint</rightRearJoint>
      <wheelSeparation>0.048</wheelSeparation>
      <wheelDiameter>0.026281</wheelDiameter>
      <robotBaseFrame>base_footprint</robotBaseFrame>
      <torque>1.0</torque>
      <commandTopic>cmd_vel</commandTopic>
      <odometryTopic>odom</odometryTopic>
      <broadcastTF>true</broadcastTF>
      <odometryFrame>odom</odometryFrame>
      <covariance_x>0.0001</covariance_x>
      <covariance_y>0.0001</covariance_y>
      <covariance_yaw>0.001</covariance_yaw>
    </plugin>
  </gazebo>
  <link name="camera_link"/>
  <joint name="head_camera_joint" type="fixed">
    <parent link="head"/>
    <child link="camera_link"/>
    <origin rpy="0 0 0" xyz="0.020813 0 -0.0071471"/>
  </joint>
  <gazebo reference="camera_link">
    <sensor name="vector_camera" type="camera">
      <update_rate>10.0</update_rate>
      <camera name="headcamera">
        <horizontal_fov>1.3962634</horizontal_fov>
        <image>
          <width>1280</width>
          <height>720</height>
          <format>R8G8B8</format>
        </image>
        <clip>
          <near>0.01</near>
          <far>100</far>
        </clip>
        <noise>
          <type>gaussian</type>
          <mean>0.0</mean>
          <stddev>0.007</stddev>
        </noise>
      </camera>
      <plugin filename="libgazebo_ros_camera.so" name="camera_controller">
        <alwaysOn>true</alwaysOn>
        <updateRate>10.0</updateRate>
        <cameraName>camera</cameraName>
        <imageTopicName>/vector/camera</imageTopicName>
        <cameraInfoTopicName>/vector/camera_info</cameraInfoTopicName>
        <frameName>camera_link</frameName>
        <hackBaseline>0.07</hackBaseline>
        <distortionK1>0.0</distortionK1>
        <distortionK2>0.0</distortionK2>
        <distortionK3>0.0</distortionK3>
        <distortionT1>0.0</distortionT1>
        <distortionT2>0.0</distortionT2>
      </plugin>
    </sensor>
  </gazebo>
  <link name="drop_fl"/>
  <joint name="drop_fl_joint" type="fixed">
    <parent link="base_link"/>
    <child link="drop_fl"/>
    <origin rpy="0 1.57 0" xyz="0.0351028 0.01 -0.0213898"/>
  </joint>
  <gazebo reference="drop_fl">
    <sensor name="ranger" type="ray">
      <pose>0 0 0 0 0 0</pose>
      <visualize>true</visualize>
      <update_rate>50</update_rate>
      <ray>
        <scan>
          <horizontal>
            <samples>10</samples>
            <resolution>1</resolution>
            <min_angle>-0.14835</min_angle>
            <max_angle>0.14835</max_angle>
          </horizontal>
          <vertical>
            <samples>10</samples>
            <resolution>1</resolution>
            <min_angle>-0.14835</min_angle>
            <max_angle>0.14835</max_angle>
          </vertical>
        </scan>
        <range>
          <min>0.001</min>
          <max>0.02</max>
          <resolution>0.02</resolution>
        </range>
      </ray>
      <plugin filename="libgazebo_ros_range.so" name="gazebo_ros_range">
        <gaussianNoise>0.005</gaussianNoise>
        <alwaysOn>true</alwaysOn>
        <updateRate>50</updateRate>
        <topicName>/vector/drop_fl</topicName>
        <frameName>drop_fl</frameName>
        <radiation>INFRARED</radiation>
        <fov>0.2967</fov>
      </plugin>
    </sensor>
  </gazebo>
  <link name="drop_fr"/>
  <joint name="drop_fr_joint" type="fixed">
    <parent link="base_link"/>
    <child link="drop_fr"/>
    <origin rpy="0 1.57 0" xyz="0.0351028 -0.01 -0.0213898"/>
  </joint>
  <gazebo reference="drop_fr">
    <sensor name="ranger" type="ray">
      <pose>0 0 0 0 0 0</pose>
      <visualize>true</visualize>
      <update_rate>50</update_rate>
      <ray>
        <scan>
          <horizontal>
            <samples>10</samples>
            <resolution>1</resolution>
            <min_angle>-0.14835</min_angle>
            <max_angle>0.14835</max_angle>
          </horizontal>
          <vertical>
            <samples>10</samples>
            <resolution>1</resolution>
            <min_angle>-0.14835</min_angle>
            <max_angle>0.14835</max_angle>
          </vertical>
        </scan>
        <range>
          <min>0.001</min>
          <max>0.02</max>
          <resolution>0.02</resolution>
        </range>
      </ray>
      <plugin filename="libgazebo_ros_range.so" name="gazebo_ros_range">
        <gaussianNoise>0.005</gaussianNoise>
        <alwaysOn>true</alwaysOn>
        <updateRate>50</updateRate>
        <topicName>/vector/drop_fr</topicName>
        <frameName>drop_fr</frameName>
        <radiation>INFRARED</radiation>
        <fov>0.2967</fov>
      </plugin>
    </sensor>
  </gazebo>
  <link name="drop_rl"/>
  <joint name="drop_rl_joint" type="fixed">
    <parent link="base_link"/>
    <child link="drop_rl"/>
    <origin rpy="0 1.57 0" xyz="-0.02 0.01 -0.0213898"/>
  </joint>
  <gazebo reference="drop_rl">
    <sensor name="ranger" type="ray">
      <pose>0 0 0 0 0 0</pose>
      <visualize>true</visualize>
      <update_rate>50</update_rate>
      <ray>
        <scan>
          <horizontal>
            <samples>10</samples>
            <resolution>1</resolution>
            <min_angle>-0.14835</min_angle>
            <max_angle>0.14835</max_angle>
          </horizontal>
          <vertical>
            <samples>10</samples>
            <resolution>1</resolution>
            <min_angle>-0.14835</min_angle>
            <max_angle>0.14835</max_angle>
          </vertical>
        </scan>
        <range>
          <min>0.001</min>
          <max>0.02</max>
          <resolution>0.02</resolution>
        </range>
      </ray>
      <plugin filename="libgazebo_ros_range.so" name="gazebo_ros_range">
        <gaussianNoise>0.005</gaussianNoise>
        <alwaysOn>true</alwaysOn>
        <updateRate>50</updateRate>
        <topicName>/vector/drop_rl</topicName>
        <frameName>drop_rl</frameName>
        <radiation>INFRARED</radiation>
        <fov>0.2967</fov>
      </plugin>
    </sensor>
  </gazebo>
  <link name="drop_rr"/>
  <joint name="drop_rr_joint" type="fixed">
    <parent link="base_link"/>
    <child link="drop_rr"/>
    <origin rpy="0 1.57 0" xyz="-0.02 -0.01 -0.0213898"/>
  </joint>
  <gazebo reference="drop_rr">
    <sensor name="ranger" type="ray">
      <pose>0 0 0 0 0 0</pose>
      <visualize>true</visualize>
      <update_rate>50</update_rate>
      <ray>
        <scan>
          <horizontal>
            <samples>10</samples>
            <resolution>1</resolution>
            <min_angle>-0.14835</min_angle>
            <max_angle>0.14835</max_angle>
          </horizontal>
          <vertical>
            <samples>10</samples>
            <resolution>1</resolution>
            <min_angle>-0.14835</min_angle>
            <max_angle>0.14835</max_angle>
          </vertical>
        </scan>
        <range>
          <min>0.001</min>
          <max>0.02</max>
          <resolution>0.02</resolution>
        </range>
      </ray>
      <plugin filename="libgazebo_ros_range.so" name="gazebo_ros_range">
        <gaussianNoise>0.005</gaussianNoise>
        <alwaysOn>true</alwaysOn>
        <updateRate>50</updateRate>
        <topicName>/vector/drop_rr</topicName>
        <frameName>drop_rr</frameName>
        <radiation>INFRARED</radiation>
        <fov>0.2967</fov>
      </plugin>
    </sensor>
  </gazebo>
  <link name="tof_link"/>
  <joint name="tof_joint" type="fixed">
    <parent link="base_link"/>
    <child link="tof_link"/>
    <origin rpy="0 0 0" xyz="0.043 0 -0.005"/>
  </joint>
  <gazebo reference="tof_link">
    <sensor name="tof_link" type="ray">
      <pose>0 0 0 0 0 0</pose>
      <visualize>true</visualize>
      <update_rate>10.0</update_rate>
      <ray>
        <scan>
          <horizontal>
            <samples>4</samples>
            <resolution>1</resolution>
            <min_angle>-0.01</min_angle>
            <max_angle>0.01</max_angle>
          </horizontal>
          <vertical>
            <samples>4</samples>
            <resolution>1</resolution>
            <min_angle>-0.01</min_angle>
            <max_angle>0.01</max_angle>
          </vertical>
        </scan>
        <range>
          <min>0.0</min>
          <max>0.4</max>
          <resolution>0.01</resolution>
        </range>
        <noise>
          <type>gaussian</type>
          <mean>0.01</mean>
          <stddev>0.01</stddev>
        </noise>
      </ray>
      <plugin filename="libgazebo_ros_range.so" name="gazebo_ros_range">
        <gaussianNoise>0.01</gaussianNoise>
        <topicName>/vector/laser</topicName>
        <frameName>tof_link</frameName>
        <radiation>INFRARED</radiation>
        <updateRate>10</updateRate>
        <fov>0.02</fov>
      </plugin>
    </sensor>
  </gazebo>
  <link name="imu"/>
  <joint name="imu_joint" type="fixed">
    <parent link="head"/>
    <child link="imu"/>
    <origin rpy="0 0 0" xyz="0.0 0 0.0"/>
  </joint>
  <gazebo reference="imu">
    <gravity>true</gravity>
    <sensor name="imu_sensor" type="imu">
      <always_on>true</always_on>
      <update_rate>100</update_rate>
      <visualize>true</visualize>
      <topic>vector/imu</topic>
      <plugin filename="libgazebo_ros_imu_sensor.so" name="imu_plugin">
        <topicName>vector/imu</topicName>
        <bodyName>imu</bodyName>
        <updateRateHZ>10.0</updateRateHZ>
        <gaussianNoise>2.89e-06</gaussianNoise>
        <xyzOffset>0 0 0</xyzOffset>
        <rpyOffset>0 0 0</rpyOffset>
        <frameName>imu</frameName>
      </plugin>
      <pose>0 0 0 0 0 0</pose>
    </sensor>
  </gazebo>
</robot>

